Workbook
Name OLE_LINK1: Einzelarbeit!$A$6
Name OLE_LINK1: Gruppenarbeit!$A$6
Name OLE_LINK1: Konzept!#REF!
Name OLE_LINK1: Notenblatt!$A$5
Name OLE_LINK1: Poster_Präsentation!$A$6
Name OLE_LINK1: Präsentation!$A$6
Name OLE_LINK1: Projektvereinbarung!$A$11
Name Poster_Präs.: [1]Notentabellen!$G$3:$H$13
Name Poster_Präs.: Notentabellen!$G$3:$H$13
Name Präsentation: [1]Notentabellen!$D$3:$E$13
Name Präsentation: Notentabellen!$D$3:$E$13
Name Schriftlich: [1]Notentabellen!$A$3:$B$13
Name Schriftlich: Notentabellen!$A$3:$B$13

Sheet Projektvereinbarung
A1: Projektvereinbarung für eine Maturaarbeit am Wirtschaftsgymnasium
A2: MA Typ Technische Produktion
A3: Es gelten folgende allgemeine Bestimmungen:
A4: 1. Reglement für die Maturaarbeit an den Gymnasien im Kanton Basel-Stadt
A5: 2. Leitfaden für die Maturaarbeit am Wirtschaftsgymnasium inkl. Terminplan
A6: Die Projektvereinbarung enthält folgende Teile:
A7: 1. Konzept
A8: 2. Präzisierungen
A10: Titel der Arbeit | B10: Programmierung und Optimierung eines Programmes für die Erkennung von handgeschriebenen Zahlen
A12: Einzelarbeit | C12: Gruppenarbeit
C13: zusammen mit
A15: KoreferentIn
A16: Vorname | C16: Name
A18: Poster | B18: Ja | C18: Nein
A20: Schülerin / Schüler | C20: Betreuungsperson
A21: Vorname | B21: Jan | C21: Vorname | D21: Christian
A22: Name | B22: Haag | C22: Name | D22: Datzko
A23: Klasse | B23: G3c
A24: Telefonnummer | B24: 41787409916 | C24: Telefonnummer
A25: E-Mailadresse | B25: jan.haag@stud.edubs.ch/ Jan.valentin.haag@gmail.com | C25: E-Mailadresse | D25: christian.datzko@edubs.ch
A27: Datum und Unterschriften
A28: Schülerin / Schüler | C28: Betreuungsperson
A31: Abgabeformalitäten
A32: PDF folgendermassen benennen: MA_WG_Abschlussjahr_Nachname_Vorname_Projektvereinbarung
A33: PDF zusammen mit dem Konzept und dem Präzisierungsformular per Edubs-Mail ans Sekretariat: wginfo@edubs.ch
A34: Cc des PDFs an Schüler/-in und Betreuer/-in senden

Sheet Konzept
A1: Konzept
A2: MA Typ Technische Produktion
A3: Schülerin / Schüler
A4: Vorname Name / Klasse | B4: =[1]Projektvereinbarung!B21&" "&[1]Projektvereinbarung!B22&" / "&[1]Projektvereinbarung!B23 -> /
A6: Titel der Arbeit | B6: =IF([1]Projektvereinbarung!B10="","",[1]Projektvereinbarung!B10)
A8: Typus der Arbeit | B8: (Untersuchung, kreative Produktion, technische Produktion, Organisation einer Veranstaltung)
B9: Technische Produktion
A11: Zielsetzungen | B11: (Was bei meiner Arbeit herauskommen soll / Mein eigener Untersuchungsanteil)
B12: Ich kann ein NN erstellen, optimieren und verstehen. Dieses NN kann handgeschriebene Zahlen digital lesen und in die Zahlen 0-9 kathegorisieren.
A14: Fragestellung, Thesen, Projektidee | B14: (Fragen, die ich beantworten will / Meine Vermutungen und Thesen)
B15: - Wie kann ich ein NN schreiben und optimieren, welches die Fehlerquote beim Kategorisieren von handgeschriebenen Zahlen auf ein lokales oder globales Minimum bringt? - Welche Programmiersprache eignet sich für mein Projekt am besten? - Welche Bibliotheken eignen sich für mein Programm am besten? - Mit diesem Projekt möchte ich mich mit dem heutzutage alltäglich verwendeten Begriff der AI auseinandersetzen. Ich möchte mir ein grundlegendes Verständnis über AI’s und NN’s verschaffen.
A17: Arbeitsmethoden | B17: (Mein Vorgehen)
B18: Ich schreibe mein Programm mithilfe von "Libraries". Als Informationsquelle werde ich hauptsächlich das Internet verwenden, dabei werden mir wahrscheinlich Quellen wie «Stack Overflow» besonders nützlich sein. Phase 1: Ich setze mich mit dem Aufbau von Informatikarbeiten auseinander Ich verschaffe mir Kenntnisse über den Aufbau von NN’s und deren Anforderungen (z.B. an die Programmiersprache) Analyse verschiedener Programmiersprachen und auswählen einer geeigneten Programmiersprache Phase 2: Erstellung einer Liste mit nützlichen «Libraries», welche ich in meinem Programm verwenden möchte Schreiben des Programmes und des NN’s Phase 3: Auseinandersetzung mit der Optimierung von NN’s Auseinandersetzung mit lokalen und globalen Maxima Optimierung gewisser Variabeln, um bessere Ergebnisse zu erzielen Phase 4: Fertigstellen der Dokumentation, der schriftlichen Arbeit und des Arbeitsjournales
A20: Gliederung der Arbeit (Kapitel) | B20: 1. Einleitung a. Motivation b. Zielsetzung c. Warum ich dieses Projekt mache 2. Grundlagen des Machinelearnings 3. Aufbau meines Programmes 4. Optimierung des Programmes 5. Auswertung (z.B. mittels eines Feldtestes) 6. Fazit 7. Quellenverzeichnis
A22: Eigenleistung | B22: Ich schreibe ein Programm, welches digitale Bilder von handgeschriebenen Zahlen einliest und diese korrekt kategorisiert. Das Programm beinhaltet ein NN. Das Programm werde ich mithilfe von «Libraries» schreiben. Ich werde versuchen Variablen des NN’s zu optimieren, um bessere Genauigkeit bei der Kategorisierung der Zahlen zu erzielen.
A24: Zeitplan | B24: 1.: 05.05.2023: Abgabe von Projektvereibarung, inkl. Konzept und Präzisierte Bewertungskriterien. 2.: 19.05.2023: Auseinandersetzung mit dem Aufbau von Informatikarbeiten Informationsbeschaffung vom Aufbau eines NN’s Informationsbeschaffung bezüglich der Anforderungen meines NN’s. Analyse von verschiedenen Programmiersprachen und Erstellung einer Pros und Cons Liste von verschiedenen Programmiersprachen. 3.: 22.06.2023 – 28.06.2023: Maturaarbeitswoche 1 Zwischengespräch mit Betreuungslehrperson 4.: 23.06.2023: Erstellung einer Liste mit nützlichen Libraries Erstellen des NN’s in der ausgewählten Programmiersprache 5.: 14.08.2023: Auseinandersetzung mit der Optimierung meines NN’s Auseinandersetzung mit den lokalen Maxima und den globalen Maxima. Optimierung gewisser Variablen meines NN’s. 6.: 01.09.2023: Fertigstellen des Schriftlichen Teiles der Arbeit Zusammenfassung von Notizen und Überarbeitung des Arbeitjournal 7.: 13.10.2023: Späteste Abgabe von Maturarbeit und Arbeitsjournal
A26: Datum und Unterschriften
A27: Schülerin / Schüler | B27: Betreuungsperson
A30: Abgabeformalitäten
A31: PDF folgendermassen benennen: MA_WG_Abschlussjahr_Nachname_Vorname_Konzept
A32: PDF zusammen mit der Projektvereinbarung und dem Präzisierungsformular per Edubs-Mail ans Sekretariat: wginfo@edubs.ch
A33: Cc des PDFs an Schüler/-in und Betreuer/-in senden

Sheet Notenblatt
A1: Notenblatt für | B1: =IF(Projektvereinbarung!B21="","",Projektvereinbarung!B21&" "&Projektvereinbarung!B22&", "&Projektvereinbarung!B23) -> Jan Haag, G3c
A2: MA Typ Technische Produktion
A3: Titel der Arbeit | B3: =IF(Projektvereinbarung!B10="","",Projektvereinbarung!B10) -> Programmierung und Optimierung eines Programmes für die Erkennung von handgeschriebenen Zahlen | C3: =IF(Notentabellen!A35=TRUE,Notentabellen!B35,IF(Notentabellen!A36=TRUE,Notentabellen!B36,"")) -> Einzelarbeit
A4: Teil 1 | C4: Erreichte Punkte
A5: Summe Werk | C5: =IF($C$3="Einzelarbeit",Einzelarbeit!F11,Gruppenarbeit!F11) -> 0
A6: Summe schriftlicher Teil | C6: =IF($C$3="Einzelarbeit",Einzelarbeit!F24,Gruppenarbeit!F24) -> 0
A7: Summe Arbeitsprozess | C7: =IF($C$3="Einzelarbeit",Einzelarbeit!F32,Gruppenarbeit!F33) -> 0
A8: Summe Teil 1: Werk, schriftlicher Teil, Arbeitsprozess | C8: =SUM(C5:C7) -> 0
A10: Note Teil 1 | C10: =IF(C8=0,"",VLOOKUP(C8,Schriftlich,2,TRUE))
A12: Teil 2 | C12: =IF(Notentabellen!A38=TRUE,Notentabellen!B38,IF(Notentabellen!A39=TRUE,Notentabellen!B39,"")) -> ohne Poster
A13: Summe Präsentation | C13: =IF($C$12="ohne Poster",Präsentation!E11,Poster_Präsentation!E11) -> 0
A14: Summe Poster | C14: =IF($C$12="ohne Poster",Präsentation!E12,Poster_Präsentation!E22) -> 0
A15: Summe Teil 2: Präsentation, (Poster) | C15: =SUM(C13:C14) -> 0
A17: Note Teil 2 | C17: =IF(C15=0,0,IF(C12="ohne Poster",VLOOKUP(C15,Präsentation,2,TRUE),VLOOKUP(C15,Poster_Präs.,2,TRUE))) -> 0
A19: Gesamtnote Maturaarbeit | C19: =IF(C10="","",ROUND((C10*2+C17)/3*2,0)/2)
A21: Datum
A22: Vorname, Name (Betreuungsperson) Unterschrift | B22: Unterschrift
A26: Vorname, Name (Koreferent/-in) Unterschrift | B26: Unterschrift
A31: Abgabeformalitäten
A32: PDF folgendermassen benennen: MA_WG_Abschlussjahr_Nachname_Vorname_Notenblatt
A33: PDF per Edubs-Mail ans Sekretariat: wginfo@edubs.ch Cc des PDFs an Koreferenten senden
A34: PDF bei der Endbesprechung an Schüler/-in abgeben

Sheet Einzelarbeit
A1: Präzisierungen und Bewertung für | C1: =Notenblatt!B1 -> Jan Haag, G3c
A2: MA Typ Technische Produktion
A3: =Notenblatt!A3 -> Titel der Arbeit | C3: =IF(Projektvereinbarung!B10="","",Projektvereinbarung!B10) -> Programmierung und Optimierung eines Programmes für die Erkennung von handgeschriebenen Zahlen
A4: Werk
A5: Kriterien | B5: Punkte | C5: Präzisierungen | D5: Vereinbarte Punkte | E5: Kommentar | F5: Erreichte Punkte
A6: Konstruktionsidee und Methodeneinsatz | B6: 5 - 10 | C6: · Realisation der Konstruktionsidee · Angemessenheit des technischen Verfahrens · Beherrschen bzw. Erlernen der notwendigen fachlichen Verfahren ·... | D6: 5
A7: Bewältigung des Themas | B7: 5 - 15 | C7: · Auseinandersetzung mit dem Thema · Einbringen eigener Erfahrungen auf dem Gebiet · … | D7: 10
A8: Sachliche Qualität | B8: 10 - 20 | C8: · Entstehung eines Ganzen aus Plänen, Entwürfen, Modellen · … | D8: 15
A9: Eigenständigkeit | B9: 5 - 10 | C9: · Neue bzw. modifizierte Eigenschaft des Erzeugnisses · … | D9: 5
A10: Darstellung | B10: 10 - 15 | C10: · Technische Qualität des Erzeugnisses · … | D10: 15
A11: Summe Werk | B11: 40 - 50 | D11: =IF(SUM(D6:D10)<=50,SUM(D6:D10),"max. 50 Punkte") -> 50 | F11: =IF(SUM(F6:F10)<=50,SUM(F6:F10),"max. 50 Punkte") -> 0
A12: Schriftlicher Teil
A13: Kriterien | B13: Punkte | C13: Präzisierungen | D13: Vereinbarte Punkte | E13: Kommentar | F13: Erreichte Punkte
A14: Inhalt
A15: Gestaltungsidee und Methodeneinsatz | B15: 1 - 5 | C15: · Umschreibung der Konstruktionsidee · Erklärung des Vorgehens · … | D15: 1
A16: Bewältigung des Themas | B16: 1 - 5 | C16: · Kommentar zeigt Verständnis des Problems bzw. der Gesetzmässigkeiten · Dokumentation des Entstehungshintergrundes und Entwicklungsprozesses · Angemessener Aufbau · Logische Verbindung der Teile (Einleitung, Hauptteil, Schlussteil) · ... | D16: 2
A17: Nutzung von Wissen und Quellen | B17: 4 - 8 | C17: · Verarbeitung der Quellen und Daten, Versuchsergebnisse, anderer Wissensbestände · Wahl von aktueller Literatur · Wahl von aktueller Sekundärliteratur · Verarbeitung der Sekundärliteratur · … | D17: 4
A18: Sachliche Qualität | B18: 5 - 10 | C18: · Richtigkeit der Aussagen · Begründung der eigenen Ansichten · Unterscheidung von Tatsachenaussagen und eigener Meinung · Reflexion zu Verlauf, Ergebnis und Bedeutung der Arbeit · … | D18: 5
A19: Eigenständigkeit | B19: 1 - 5 | C19: · Deklaration des eigenen Anteils am Werk · Aufzeigen des Bezugs von Theorie und Werk · Eigenständiger Aufbau der Arbeit · Reflexion und Schlussfolgerungen · ... | D19: 2
A20: Form
A21: Darstellung | B21: 5 - 10 | C21: · Gliederung · Länge der Einzelteile · Umfangvorgaben eingehalten · Layout · Wahl der Abbildungen und Tabellen · Zweckmässigkeit der Abbildungen und Tabellen · Qualität der Abbildungen und Tabellen · ... | D21: 10
A22: Sprache | B22: 4 - 8 | C22: · Sprachlicher Ausdruck · Verständlichkeit und Lesbarkeit · Grammatik und Satzbau · Orthografie und Interpunktion · Umgang mit Schlüsselbegriffen · … | D22: 4
A23: Zitate / Quellen / Verzeichnisse | B23: 1 - 5 | C23: · Zitieren (nach Vorgaben) · Ausweisung fremder Gedanken · Beschriftung von Darstellungen · Inhalts-, Quellen-, Literaturangaben · Vollständigkeit der Verzeichnisse · ... | D23: 2
A24: Summe schriftlicher Teil | B24: 30 - 40 | D24: =IF(SUM(D15:D23)<=40,SUM(D15:D23),"max. 40 Punkte") -> 30 | F24: =IF(SUM(F15:F23)<=40,SUM(F15:F23),"max. 40 Punkte") -> 0
A25: Summe Werk, schriftlicher Teil | B25: 80 | D25: =IF(SUM(D24,D11)<=80,SUM(D24,D11),"max. 80 Punkte") -> 80 | F25: =IF(SUM(F24,F11)<=80,SUM(F24,F11),"max. 80 Punkte") -> 0
A26: Arbeitsprozess
A27: Kriterien | B27: Präzisierungen | D27: Punkte | E27: Kommentar | F27: Erreichte Punkte
A28: Motivation | B28: · Initiative zu Beginn des Arbeitsprozesses · Konzentration im Arbeitsprozess · Zeitaufwand · Überwindung von Schwierigkeiten und Misserfolgen | D28: 5
A29: Selbstständigkeit | B29: · Eingrenzung der ersten kreativen Idee · Selbstständigkeit in der Planungsphase · Selbstständigkeit in der Durchführungsphase · Verarbeitung von Impulsen der Betreuungsperson · Erkennen der eigenen Grenzen · Hilfe holen bei Notwendigkeit · Fortschritte bezüglich der Technik · Reflexion des Arbeitsprozesses · Entwicklung der inhaltlichen und künstlerischen Absicht | D29: 5
A30: Vorgehensweise | B30: · Erwerben des notwendigen Wissens · Entwicklung einer machbaren Fragestellung · Methodenwahl · Überprüfung / Anpassung des Vorgehens bzw. Verfahrens · Anwendung eines Arbeits- und Zeitplans · Anpassung des Arbeits-/Zeitplans an den Verlauf · Dokumentation der Zwischenergebnisse und des Prozesses · Verständlichkeit von Konzepten und Ideenskizzen · Qualität der Entwürfe · Angemessene Planungsunterlagen · Sinnvolle Nutzung der Ressourcen | D30: 5
A31: Zuverlässigkeit | B31: · Einhaltung von Vereinbarungen · Einhaltung von Terminen/Zeitplan | D31: 5
A32: Summe Arbeitsprozess | B32: 20 | D32: =IF(SUM(D28:D31)<=20,SUM(D28:D31),"max. 20 Punkte") -> 20 | F32: =IF(SUM(F28:F31)<=20,SUM(F28:F31),"max. 20 Punkte") -> 0
A33: Summe Werk, schriftlicher Teil, Arbeitsprozess | B33: 100 | D33: =IF(SUM(D32,D25)<=100,SUM(D32,D25),"max. 100 Punkte") -> 100 | F33: =IF(SUM(F32,F25)<=100,SUM(F32,F25),"max. 100 Punkte") -> 0
A35: Datum | B35: 45051 | E35: Datum
A36: Vorname, Name (Schülerin / Schüler) Unterschrift | E36: Vorname, Name (Betreuungsperson) | F36: Unterschrift
A37: Jan, Haag | E37: Christian, Datzko
A40: Vorname, Name (Betreuungsperson) Unterschrift | E40: Vorname, Name (Koreferent/-in) | F40: Unterschrift
A41: Christian, Datzko
A45: Abgabeformalitäten für die Präzisierungen
A46: Datei folgendermassen benennen: MA_WG_Abschlussjahr_Nachname_Vorname_Präzisierungen
...

Sheet Gruppenarbeit
A1: Präzisierungen und Bewertung für | C1: =Notenblatt!B1 -> Jan Haag, G3c
A2: MA Typ Technische Produktion
A3: =Notenblatt!A3 -> Titel der Arbeit | C3: =IF(Projektvereinbarung!B10="","",Projektvereinbarung!B10) -> Programmierung und Optimierung eines Programmes für die Erkennung von handgeschriebenen Zahlen
A4: Werk
A5: Kriterien | B5: Punkte | C5: Präzisierungen | D5: Vereinbarte Punkte | E5: Kommentar | F5: Erreichte Punkte
A6: Konstruktionsidee und Methodeneinsatz | B6: 5 - 10 | C6: · Realisation der Konstruktionsidee · Angemessenheit des technischen Verfahrens · Beherrschen bzw. Erlernen der notwendigen fachlichen Verfahren ·...
A7: Bewältigung des Themas | B7: 5 - 15 | C7: · Auseinandersetzung mit dem Thema · Einbringen eigener Erfahrungen auf dem Gebiet · …
A8: Sachliche Qualität | B8: 10 - 20 | C8: · Entstehung eines Ganzen aus Plänen, Entwürfen, Modellen · …
A9: Eigenständigkeit | B9: 5 - 10 | C9: · Neue bzw. modifizierte Eigenschaft des Erzeugnisses · …
A10: Darstellung | B10: 10 - 15 | C10: · Technische Qualität des Erzeugnisses · …
A11: Summe Werk | B11: 40 - 50 | D11: =IF(SUM(D6:D10)<=50,SUM(D6:D10),"max. 50 Punkte") -> 0 | F11: =IF(SUM(F6:F10)<=50,SUM(F6:F10),"max. 50 Punkte") -> 0
A12: Schriftlicher Teil
A13: Kriterien | B13: Punkte | C13: Präzisierungen | D13: Vereinbarte Punkte | E13: Kommentar | F13: Erreichte Punkte
A14: Inhalt
A15: Gestaltungsidee und Methodeneinsatz | B15: 1 - 5 | C15: · Umschreibung der Konstruktionsidee · Erklärung des Vorgehens · …
A16: Bewältigung des Themas | B16: 1 - 5 | C16: · Kommentar zeigt Verständnis des Problems bzw. der Gesetzmässigkeiten · Dokumentation des Entstehungshintergrundes und Entwicklungsprozesses · Angemessener Aufbau · Logische Verbindung der Teile (Einleitung, Hauptteil, Schlussteil) · ...
A17: Nutzung von Wissen und Quellen | B17: 4 - 8 | C17: · Verarbeitung der Quellen und Daten, Versuchsergebnisse, anderer Wissensbestände · Wahl von aktueller Literatur · Wahl von aktueller Sekundärliteratur · Verarbeitung der Sekundärliteratur · …
A18: Sachliche Qualität | B18: 5 - 10 | C18: · Richtigkeit der Aussagen · Begründung der eigenen Ansichten · Unterscheidung von Tatsachenaussagen und eigener Meinung · Reflexion zu Verlauf, Ergebnis und Bedeutung der Arbeit · …
A19: Eigenständigkeit | B19: 1 - 5 | C19: · Deklaration des eigenen Anteils am Werk · Aufzeigen des Bezugs von Theorie und Werk · Eigenständiger Aufbau der Arbeit · Reflexion und Schlussfolgerungen · ...
A20: Form
A21: Darstellung | B21: 5 - 10 | C21: · Gliederung · Länge der Einzelteile · Umfangvorgaben eingehalten · Layout · Wahl der Abbildungen und Tabellen · Zweckmässigkeit der Abbildungen und Tabellen · Qualität der Abbildungen und Tabellen · ...
A22: Sprache | B22: 4 - 8 | C22: · Sprachlicher Ausdruck · Verständlichkeit und Lesbarkeit · Grammatik und Satzbau · Orthografie und Interpunktion · Umgang mit Schlüsselbegriffen · …
A23: Zitate / Quellen / Verzeichnisse | B23: 1 - 5 | C23: · Zitieren (nach Vorgaben) · Ausweisung fremder Gedanken · Beschriftung von Darstellungen · Inhalts-, Quellen-, Literaturangaben · Vollständigkeit der Verzeichnisse · ...
A24: Summe schriftlicher Teil | B24: 30 - 40 | D24: =IF(SUM(D15:D23)<=40,SUM(D15:D23),"max. 40 Punkte") -> 0 | F24: =IF(SUM(F15:F23)<=40,SUM(F15:F23),"max. 40 Punkte") -> 0
A25: Summe Werk, schriftlicher Teil | B25: 80 | D25: =IF(SUM(D24,D11)<=80,SUM(D24,D11),"max. 80 Punkte") -> 0 | F25: =IF(SUM(F24,F11)<=80,SUM(F24,F11),"max. 80 Punkte") -> 0
A26: Arbeitsprozess
A27: Kriterien | B27: Präzisierungen | D27: Punkte | E27: Kommentar | F27: Erreichte Punkte
A28: Motivation | B28: · Initiative zu Beginn des Arbeitsprozesses · Konzentration im Arbeitsprozess · Zeitaufwand · Überwindung von Schwierigkeiten und Misserfolgen | D28: 4
A29: Selbstständigkeit | B29: · Eingrenzung der ersten kreativen Idee · Selbstständigkeit in der Planungsphase · Selbstständigkeit in der Durchführungsphase · Verarbeitung von Impulsen der Betreuungsperson · Erkennen der eigenen Grenzen · Hilfe holen bei Notwendigkeit · Fortschritte bezüglich der Technik · Reflexion des Arbeitsprozesses · Entwicklung der inhaltlichen und künstlerischen Absicht | D29: 4
A30: Vorgehensweise | B30: · Erwerben des notwendigen Wissens · Entwicklung einer machbaren Fragestellung · Methodenwahl · Überprüfung / Anpassung des Vorgehens bzw. Verfahrens · Anwendung eines Arbeits- und Zeitplans · Anpassung des Arbeits-/Zeitplans an den Verlauf · Dokumentation der Zwischenergebnisse und des Prozesses · Verständlichkeit von Konzepten und Ideenskizzen · Qualität der Entwürfe · Angemessene Planungsunterlagen · Sinnvolle Nutzung der Ressourcen | D30: 4
A31: Zuverlässigkeit | B31: · Einhaltung von Vereinbarungen · Einhaltung von Terminen/Zeitplan | D31: 4
A32: Teamspezifische Aspekte bei Gruppenarbeiten | B32: · Vorgehen nach Arbeits- und Zeitplan · Sinnvolle Arbeitsorganisation im Team · Ausgewogene Anteile beider Teammitglieder · Geklärte Verantwortlichkeit im Team · Effizienz der Besprechungen · Bearbeitung von Konflikten | D32: 4
A33: Summe Arbeitsprozess | B33: 20 | D33: =IF(SUM(D28:D32)<=20,SUM(D28:D32),"max. 20 Punkte") -> 20 | F33: =IF(SUM(F28:F32)<=20,SUM(F28:F32),"max. 20 Punkte") -> 0
A34: Summe Werk, schriftlicher Teil, Arbeitsprozess | B34: 100 | D34: =IF(SUM(D33,D25)<=100,SUM(D33,D25),"max. 100 Punkte") -> 20 | F34: =IF(SUM(F33,F25)<=100,SUM(F33,F25),"max. 100 Punkte") -> 0
A36: Datum | E36: Datum
A37: Vorname, Name (Schülerin / Schüler) Unterschrift | E37: Vorname, Name (Betreuungsperson) | F37: Unterschrift
A41: Vorname, Name (Betreuungsperson) Unterschrift | E41: Vorname, Name (Koreferent/-in) | F41: Unterschrift
A46: Abgabeformalitäten für die Präzisierungen
A47: Datei folgendermassen benennen: MA_WG_Abschlussjahr_Nachname_Vorname_Präzisierungen
A48: Nur die Register 'Konzept', 'Projektvereinbarung' und 'Einzelarbeit oder Gruppenarbeit' als PDF per Edubs-Mail ans Sekretariat: wginfo@edubs.ch Cc des PDFs an Koreferenten senden
...

Sheet Präsentation
A1: Präzisierungen und Bewertung für | C1: =Notenblatt!B1 -> Jan Haag, G3c
A2: MA Typ Technische Produktion
A3: =Notenblatt!A3 -> Titel der Arbeit | C3: =IF(Projektvereinbarung!B10="","",Projektvereinbarung!B10) -> Programmierung und Optimierung eines Programmes für die Erkennung von handgeschriebenen Zahlen
A4: Präsentation
A5: Kriterien | B5: Gesetzte Punkte | C5: Präzisierungen | D5: Kommentar | E5: Erreichte Punkte
A6: Struktur | B6: 3 | C6: · Gliederung · Rhythmisierung · Wissensaufbau
A7: Inhaltliche Sicherheit | B7: 15 | C7: · Auswahl des Inhalts · Neuer Aspekt · Darlegung der persönlichen Erkenntnisse und Erfahrungen · Beantwortung der Fragen
A8: Sprache | B8: 10 | C8: · Verständlichkeit · Korrektheit · Sprachfluss · Lautstärke und Tempo
A9: Medien und Hilfsmittel | B9: 4 | C9: · Medienwahl · Umgang mit Medien und technischen Hilfsmitteln
A10: Interaktion | B10: 8 | C10: · Auftreten · Freie Rede · Interesse wecken · Einbezug des Publikums
A11: Summe Präsentation | B11: 40 | E11: =IF(SUM(E6:E10)<=40,SUM(E6:E10),"max. 40 Punkte") -> 0
A13: Datum
A14: Vorname, Name (Schülerin / Schüler) Unterschrift
A18: Vorname, Name (Betreuungsperson) Unterschrift
A24: Abgabeformalitäten für die Präzisierungen
A25: Datei folgendermassen benennen: MA_WG_Abschlussjahr_Nachname_Vorname_Präzisierungen
A26: Nur die Register 'Konzept', 'Projektvereinbarung' und 'Einzelarbeit oder Gruppenarbeit' als PDF per Edubs-Mail ans Sekretariat: wginfo@edubs.ch Cc des PDFs an Koreferenten senden
A28: PDF bei der Besprechung an Schüler/-in abgeben
A30: Abgabeformalitäten für die Bewertung
A31: Datei folgendermassen benennen: MA_WG_Abschlussjahr_Nachname_Vorname_Bewertung
A32: Nur die Register 'Notenblatt' und 'Einzelarbeit oder Gruppenarbeit' als PDF per Edubs-Mail ans Sekretariat: wginfo@edubs.ch Cc des PDFs an Koreferenten senden
A34: KEINE Kopie geht an den SuS

Sheet Poster_Präsentation
A1: Präzisierungen und Bewertung für | C1: =Notenblatt!B1 -> Jan Haag, G3c
A2: MA Typ Technische Produktion
A3: =Notenblatt!A3 -> Titel der Arbeit | C3: =IF(Projektvereinbarung!B10="","",Projektvereinbarung!B10) -> Programmierung und Optimierung eines Programmes für die Erkennung von handgeschriebenen Zahlen
A4: Präsentation
A5: Kriterien | B5: Gesetzte Punkte | C5: Präzisierungen | D5: Kommentar | E5: Erreichte Punkte
A6: Struktur | B6: 3 | C6: · Gliederung · Rhythmisierung · Wissensaufbau
A7: Inhaltliche Sicherheit | B7: 15 | C7: · Auswahl des Inhalts · Neuer Aspekt · Darlegung der persönlichen Erkenntnisse und Erfahrungen · Beantwortung der Fragen
A8: Sprache | B8: 10 | C8: · Verständlichkeit · Korrektheit · Sprachfluss · Lautstärke und Tempo
A9: Medien und Hilfsmittel | B9: 4 | C9: · Medienwahl · Umgang mit Medien und technischen Hilfsmitteln
A10: Interaktion | B10: 8 | C10: · Auftreten · Freie Rede · Interesse wecken · Einbezug des Publikums
A11: Summe Präsentation | B11: 40 | E11: =IF(SUM(E6:E10)<=40,SUM(E6:E10),"max. 40 Punkte") -> 0
A12: Poster
A13: Kriterien | B13: Gesetzte Punkte | C13: Präzisierungen | D13: Kommentar | E13: Erreichte Punkte
A14: Inhalt
A15: Fragestellung / Grundgedanke | B15: 10 | C15: · Themendarstellung · Klarheit · Beschränkung aufs Wesentliche
A16: Arbeitsergebnis | C16: · Verständlichkeit · Schlüssigkeit
A17: Interpretation | C17: · Nachvollziehbarkeit
A18: Visualisierung
A19: Kreativität | B19: 10 | C19: · Poster erregt Aufmerksamkeit · Gestaltungsideen · Grafiken und Bilder unterstützen Aussage und Inhalt · Typografie · Materialien
A20: Layout | C20: · Anordnung · Gewichtung
A21: Qualität | C21: · Saubere Verarbeitung · Technik · Zitate / Quellen / Verzeichnisse
A22: Summe Poster | B22: 20 | E22: =IF(SUM(E15:E21)<=20,SUM(E15:E21),"max. 20 Punkte") -> 0
A24: Datum
A25: Vorname, Name (Schülerin / Schüler) Unterschrift
A29: Vorname, Name (Betreuungsperson) Unterschrift
A34: Abgabeformalitäten für die Präzisierungen
A35: Datei folgendermassen benennen: MA_WG_Abschlussjahr_Nachname_Vorname_Präzisierungen
A36: Nur die Register 'Konzept', 'Projektvereinbarung' und 'Einzelarbeit oder Gruppenarbeit' als PDF per Edubs-Mail ans Sekretariat: wginfo@edubs.ch Cc des PDFs an Koreferenten senden
A38: PDF bei der Besprechung an Schüler/-in abgeben
A40: Abgabeformalitäten für die Bewertung
A41: Datei folgendermassen benennen: MA_WG_Abschlussjahr_Nachname_Vorname_Bewertung
A42: Nur die Register 'Notenblatt' und 'Einzelarbeit oder Gruppenarbeit' als PDF per Edubs-Mail ans Sekretariat: wginfo@edubs.ch Cc des PDFs an Koreferenten senden
A44: KEINE Kopie geht an den SuS

Sheet Notentabellen
A1: Umrechnung: schriftliche Arbeit und Arbeitsprozess | D1: Umrechnung: mündliche Präsentation | G1: Umrechnung: Poster / mündliche Präsentation
A2: Punkte | B2: Note | D2: Punkte | E2: Note | G2: Punkte | H2: Note
A3: 0 | B3: 1 | D3: 0 | E3: 1 | G3: 0 | H3: 1
A4: 5 | B4: 1.5 | D4: 2 | E4: 1.5 | G4: 3 | H4: 1.5
A5: 15 | B5: 2 | D5: 6 | E5: 2 | G5: 9 | H5: 2
A6: 25 | B6: 2.5 | D6: 10 | E6: 2.5 | G6: 15 | H6: 2.5
A7: 35 | B7: 3 | D7: 14 | E7: 3 | G7: 21 | H7: 3
A8: 45 | B8: 3.5 | D8: 18 | E8: 3.5 | G8: 27 | H8: 3.5
A9: 55 | B9: 4 | D9: 22 | E9: 4 | G9: 33 | H9: 4
A10: 65 | B10: 4.5 | D10: 26 | E10: 4.5 | G10: 39 | H10: 4.5
A11: 75 | B11: 5 | D11: 30 | E11: 5 | G11: 45 | H11: 5
A12: 85 | B12: 5.5 | D12: 34 | E12: 5.5 | G12: 51 | H12: 5.5
A13: 95 | B13: 6 | D13: 38 | E13: 6 | G13: 57 | H13: 6
A35: TRUE | B35: Einzelarbeit
A36: FALSE | B36: Gruppenarbeit
A38: FALSE | B38: mit Poster
A39: TRUE | B39: ohne Poster
